<?xml version="1.0" ?>
<mujoco model="test">
	<visual>
		<map force="0.1" zfar="30"/>
		<rgba haze="0.15 0.25 0.35 1"/>
		<global offwidth="2560" offheight="1440" elevation="-20" azimuth="120"/>
	</visual>
	<statistic center="0 0 0.7"/>
	<default>
		<default class="body">
			<geom type="capsule" condim="1" friction=".7" solimp=".9 .99 .003" solref=".015 1"/>
			<joint type="hinge" damping=".2" stiffness="1" armature=".01" limited="true" solimplimit="0 .99 .01"/>
			<default class="body_main">
				<geom type="sphere" size="0.09" rgba="0 .84 .91 1"/>
			</default>
		</default>
	</default>
	<worldbody>
		<light diffuse=".5 .5 .5" pos="0 0 10" dir="0 0 -1"/>
		<geom type="plane" size="40 40 0.1" rgba="1 1 1 1"/>
		<body name="body_main" pos="0 0 .1" childclass="body">
			<site name="body"/>
			<freejoint name="root"/>
			<geom name="body_main" class="body_main"/>
			<body name="Leg 0-0-0">
				<geom pos="1.653273178848927e-17 -0.135 0" size="0.027 0.045" euler="90 -180.0 0" rgba="0.0 0.8414709848078965 0.9092974268256817 1"/>
				<joint name="LJ0-0-0" range="0 25.0" axis="1.0 1.2246467991473532e-16 0" pos="1.1021821192326179e-17 -0.09 0" springref="25.0"/>
				<body name="Leg 0-0-1">
					<geom pos="2.645237086158283e-17 -0.216 0" size="0.021599999999999998 0.036" euler="90 -180.0 0" rgba="0.19866933079506122 0.9320390859672263 0.8084964038195901 1"/>
					<joint name="LJ0-0-1" range="0 25.0" axis="1.0 1.2246467991473532e-16 0" pos="2.2043642384652358e-17 -0.18 0" springref="25.0" stiffness="15"/>
					<body name="Leg 0-0-2">
						<geom pos="3.438808212005767e-17 -0.28079999999999994 0" size="0.01728 0.0288" euler="90 -180.0 0" rgba="0.3894183423086505 0.9854497299884601 0.675463180551151 1"/>
						<joint name="LJ0-0-2" range="0 25.0" axis="1.0 1.2246467991473532e-16 0" pos="3.08610993385133e-17 -0.252 0" springref="25.0" stiffness="15"/>
						<body name="Leg 0-0-3">
							<geom pos="4.0736651126837547e-17 -0.33263999999999994 0" size="0.013824000000000001 0.02304" euler="90 -180.0 0" rgba="0.5646424733950354 0.9995736030415051 0.5155013718214642 1"/>
							<joint name="LJ0-0-3" range="0 25.0" axis="1.0 1.2246467991473532e-16 0" pos="3.7915064901602054e-17 -0.3096 0" springref="25.0" stiffness="15"/>
						</body>
					</body>
				</body>
			</body>
			<body name="Leg 0-1-0">
				<geom pos="0.11691342951089925 0.06749999999999996 0" size="0.027 0.045" euler="90 -420.0 0" rgba="0.0 0.8414709848078965 0.9092974268256817 1"/>
				<joint name="LJ0-1-0" range="0 25.0" axis="-0.4999999999999997 0.8660254037844388 0" pos="0.07794228634059949 0.04499999999999997 0" springref="25.0"/>
				<body name="Leg 0-1-1">
					<geom pos="0.1870614872174388 0.10799999999999994 0" size="0.021599999999999998 0.036" euler="90 -420.0 0" rgba="0.19866933079506122 0.9320390859672263 0.8084964038195901 1"/>
					<joint name="LJ0-1-1" range="0 25.0" axis="-0.4999999999999997 0.8660254037844388 0" pos="0.15588457268119899 0.08999999999999994 0" springref="25.0" stiffness="15"/>
					<body name="Leg 0-1-2">
						<geom pos="0.24317993338267035 0.14039999999999989 0" size="0.01728 0.0288" euler="90 -420.0 0" rgba="0.3894183423086505 0.9854497299884601 0.675463180551151 1"/>
						<joint name="LJ0-1-2" range="0 25.0" axis="-0.4999999999999997 0.8660254037844388 0" pos="0.2182384017536786 0.12599999999999992 0" springref="25.0" stiffness="15"/>
						<body name="Leg 0-1-3">
							<geom pos="0.28807469031485566 0.16631999999999988 0" size="0.013824000000000001 0.02304" euler="90 -420.0 0" rgba="0.5646424733950354 0.9995736030415051 0.5155013718214642 1"/>
							<joint name="LJ0-1-3" range="0 25.0" axis="-0.4999999999999997 0.8660254037844388 0" pos="0.26812146501166223 0.1547999999999999 0" springref="25.0" stiffness="15"/>
						</body>
					</body>
				</body>
			</body>
			<body name="secondaryBody0-0">
				<geom name="secondaryBody0-0" pos="-0.15588457268119893 0.09000000000000001 0" class="body_main" rgba="0.09983341664682815 0.8912073600614354 0.8632093666488737 1"/>
				<joint name="BJ0-0" range="-60 60" pos="0.0 0.0 0"/>
				<body name="Leg 1-0-0">
					<geom pos="-0.22338457268119882 -0.026913429510899284 0" size="0.027 0.045" euler="90 -570.0 0" rgba="0.017999028015746276 0.8510595865292049 0.9016598860500838 1"/>
					<joint name="LJ1-0-0" range="0 25.0" axis="0.8660254037844392 -0.49999999999999917 0" pos="-0.20088457268119886 0.01205771365940049 0" springref="25.0"/>
					<body name="Leg 1-0-1">
						<geom pos="-0.26388457268119875 -0.09706148721743883 0" size="0.021599999999999998 0.036" euler="90 -570.0 0" rgba="0.2162773930243038 0.9384101870865431 0.7977729828417196 1"/>
						<joint name="LJ1-0-1" range="0 25.0" axis="0.8660254037844392 -0.49999999999999917 0" pos="-0.2458845726811988 -0.06588457268119903 0" springref="25.0" stiffness="15"/>
						<body name="Leg 1-0-2">
							<geom pos="-0.2962845726811987 -0.15317993338267044 0" size="0.01728 0.0288" euler="90 -570.0 0" rgba="0.40593346087576293 0.9883493348093304 0.6620813883256834 1"/>
							<joint name="LJ1-0-2" range="0 25.0" axis="0.8660254037844392 -0.49999999999999917 0" pos="-0.2818845726811987 -0.12823840175367868 0" springref="25.0" stiffness="15"/>
							<body name="Leg 1-0-3">
								<geom pos="-0.3222045726811986 -0.19807469031485575 0" size="0.013824000000000001 0.02304" euler="90 -570.0 0" rgba="0.5794062426392174 0.9988861134699528 0.4999946981757423 1"/>
								<joint name="LJ1-0-3" range="0 25.0" axis="0.8660254037844392 -0.49999999999999917 0" pos="-0.31068457268119865 -0.17812146501166232 0" springref="25.0" stiffness="15"/>
							</body>
						</body>
					</body>
				</body>
				<body name="Leg 1-1-0">
					<geom pos="-0.08838457268119905 0.2069134295108993 0" size="0.027 0.045" euler="90 -750.0 0" rgba="0.017999028015746276 0.8510595865292049 0.9016598860500838 1"/>
					<joint name="LJ1-1-0" range="0 25.0" axis="-0.8660254037844392 0.49999999999999906 0" pos="-0.11088457268119901 0.16794228634059954 0" springref="25.0"/>
					<body name="Leg 1-1-1">
						<geom pos="-0.04788457268119914 0.27706148721743884 0" size="0.021599999999999998 0.036" euler="90 -750.0 0" rgba="0.2162773930243038 0.9384101870865431 0.7977729828417196 1"/>
						<joint name="LJ1-1-1" range="0 25.0" axis="-0.8660254037844392 0.49999999999999906 0" pos="-0.0658845726811991 0.24588457268119907 0" springref="25.0" stiffness="15"/>
						<body name="Leg 1-1-2">
							<geom pos="-0.015484572681199238 0.3331799333826705 0" size="0.01728 0.0288" euler="90 -750.0 0" rgba="0.40593346087576293 0.9883493348093304 0.6620813883256834 1"/>
							<joint name="LJ1-1-2" range="0 25.0" axis="-0.8660254037844392 0.49999999999999906 0" pos="-0.02988457268119918 0.30823840175367867 0" springref="25.0" stiffness="15"/>
							<body name="Leg 1-1-3">
								<geom pos="0.010435427318800733 0.3780746903148558 0" size="0.013824000000000001 0.02304" euler="90 -750.0 0" rgba="0.5794062426392174 0.9988861134699528 0.4999946981757423 1"/>
								<joint name="LJ1-1-3" range="0 25.0" axis="-0.8660254037844392 0.49999999999999906 0" pos="-0.0010845726811992418 0.35812146501166237 0" springref="25.0" stiffness="15"/>
							</body>
						</body>
					</body>
				</body>
				<body name="secondaryBody1-0">
					<geom name="secondaryBody1-0" pos="-0.3117691453623979 0.17999999999999997 0" class="body_main" rgba="0.19866933079506122 0.9320390859672263 0.8084964038195901 1"/>
					<joint name="BJ1-0" range="-60 60" pos="-0.15588457268119893 0.09000000000000001 0"/>
					<body name="Leg 2-0-0">
						<geom pos="-0.42868257487329703 0.11249999999999975 0" size="0.027 0.045" euler="90 -960.0 0" rgba="0.03599222450386925 0.8603724523894668 0.893730215359041 1"/>
						<joint name="LJ2-0-0" range="0 25.0" axis="0.5000000000000016 -0.8660254037844377 0" pos="-0.3897114317029973 0.13499999999999984 0" springref="25.0"/>
						<body name="Leg 2-0-1">
							<geom pos="-0.49883063257983645 0.07199999999999963 0" size="0.021599999999999998 0.036" euler="90 -960.0 0" rgba="0.23381538327018064 0.9444772515143676 0.786791090396251 1"/>
							<joint name="LJ2-0-1" range="0 25.0" axis="0.5000000000000016 -0.8660254037844377 0" pos="-0.4676537180435967 0.08999999999999969 0" springref="25.0" stiffness="15"/>
							<body name="Leg 2-0-2">
								<geom pos="-0.5549490787450679 0.03959999999999955 0" size="0.01728 0.0288" euler="90 -960.0 0" rgba="0.4223170605526193 0.990928723091709 0.6484850875222241 1"/>
								<joint name="LJ2-0-2" range="0 25.0" axis="0.5000000000000016 -0.8660254037844377 0" pos="-0.5300075471160762 0.053999999999999576 0" springref="25.0" stiffness="15"/>
								<body name="Leg 2-0-3">
									<geom pos="-0.5998438356772533 0.01367999999999947 0" size="0.013824000000000001 0.02304" euler="90 -960.0 0" rgba="0.5939822893293754 0.9978749935357977 0.48432603062171753 1"/>
									<joint name="LJ2-0-3" range="0 25.0" axis="0.5000000000000016 -0.8660254037844377 0" pos="-0.5798906103740598 0.0251999999999995 0" springref="25.0" stiffness="15"/>
								</body>
							</body>
						</body>
					</body>
					<body name="Leg 2-1-0">
						<geom pos="-0.311769145362398 0.31499999999999995 0" size="0.027 0.045" euler="90 -1080.0 0" rgba="0.03599222450386925 0.8603724523894668 0.893730215359041 1"/>
						<joint name="LJ2-1-0" range="0 25.0" axis="-1.0 -7.347880794884119e-16 0" pos="-0.31176914536239797 0.26999999999999996 0" springref="25.0"/>
						<body name="Leg 2-1-1">
							<geom pos="-0.3117691453623981 0.39599999999999996 0" size="0.021599999999999998 0.036" euler="90 -1080.0 0" rgba="0.23381538327018064 0.9444772515143676 0.786791090396251 1"/>
							<joint name="LJ2-1-1" range="0 25.0" axis="-1.0 -7.347880794884119e-16 0" pos="-0.311769145362398 0.36 0" springref="25.0" stiffness="15"/>
							<body name="Leg 2-1-2">
								<geom pos="-0.31176914536239814 0.4607999999999999 0" size="0.01728 0.0288" euler="90 -1080.0 0" rgba="0.4223170605526193 0.990928723091709 0.6484850875222241 1"/>
								<joint name="LJ2-1-2" range="0 25.0" axis="-1.0 -7.347880794884119e-16 0" pos="-0.3117691453623981 0.43199999999999994 0" springref="25.0" stiffness="15"/>
								<body name="Leg 2-1-3">
									<geom pos="-0.31176914536239814 0.5126399999999999 0" size="0.013824000000000001 0.02304" euler="90 -1080.0 0" rgba="0.5939822893293754 0.9978749935357977 0.48432603062171753 1"/>
									<joint name="LJ2-1-3" range="0 25.0" axis="-1.0 -7.347880794884119e-16 0" pos="-0.31176914536239814 0.4895999999999999 0" springref="25.0" stiffness="15"/>
								</body>
							</body>
						</body>
					</body>
				</body>
			</body>
		</body>
	</worldbody>
	<actuator>
		<motor name="LJ0-0-0" gear="30" joint="LJ0-0-0"/>
		<motor name="LJ0-1-0" gear="30" joint="LJ0-1-0"/>
		<motor name="BJ0-0" gear="30" joint="BJ0-0"/>
		<motor name="LJ1-0-0" gear="30" joint="LJ1-0-0"/>
		<motor name="LJ1-1-0" gear="30" joint="LJ1-1-0"/>
		<motor name="BJ1-0" gear="30" joint="BJ1-0"/>
		<motor name="LJ2-0-0" gear="30" joint="LJ2-0-0"/>
		<motor name="LJ2-1-0" gear="30" joint="LJ2-1-0"/>
	</actuator>
	<sensor>
		<framepos objtype="site" objname="body"/>
		<framequat objtype="site" objname="body"/>
		<jointpos joint="LJ0-0-0"/>
		<jointpos joint="LJ0-1-0"/>
		<jointpos joint="LJ1-0-0"/>
		<jointpos joint="LJ1-1-0"/>
		<jointpos joint="LJ2-0-0"/>
		<jointpos joint="LJ2-1-0"/>
	</sensor>
</mujoco>
